Workbook

Sheet Utama
B1: ELEKTRONIK LEMBAR KERJA EVALUASI ZONA INTEGRITAS (e-LKE ZI) PADA LEMBAGA PEMASYARAKATAN KELAS IIA BANCEUY BANDUNG
B2: WBBM
A4: 1 | B4: Area Perubahan | H4: Bobot | I4: Pemenuhan | J4: Reform | K4: Nilai | L4: % | M4: Pemenuhan Nilai Min
A5: 3 | B5: A. | C5: PENGUNGKIT | H5: 60
A6: 5 | D6: 1. | E6: MANAJEMEN PERUBAHAN | H6: 8 | I6: =Jawaban!O4 -> 4 | J6: =Jawaban!O123 -> 4 | K6: =SUM(I6:J6) -> 8 | L6: =K6/H6 -> 1 | M6: =IF(AND($B$2="WBK",L6>=60%),"OK",IF(AND($B$2="WBBM",L6>=75%),"OK","Tidak Lulus")) -> OK
A7: 22 | D7: 2. | E7: PENATAAN TATALAKSANA | H7: 7 | I7: =Jawaban!O21 -> 3.5 | J7: =Jawaban!O135 -> 3.5 | K7: =SUM(I7:J7) -> 7 | L7: =K7/H7 -> 1 | M7: =IF(AND($B$2="WBK",L7>=60%),"OK",IF(AND($B$2="WBBM",L7>=75%),"OK","Tidak Lulus")) -> OK
A8: 35 | D8: 3. | E8: PENATAAN SISTEM MANAJEMEN SDM APARATUR | H8: 10 | I8: =Jawaban!O34 -> 5 | J8: =Jawaban!O145 -> 5 | K8: =SUM(I8:J8) -> 10 | L8: =K8/H8 -> 1 | M8: =IF(AND($B$2="WBK",L8>=60%),"OK",IF(AND($B$2="WBBM",L8>=75%),"OK","Tidak Lulus")) -> OK
A9: 60 | D9: 4. | E9: PENGUATAN AKUNTABILITAS | H9: 10 | I9: =Jawaban!O59 -> 5 | J9: =Jawaban!O155 -> 5 | K9: =SUM(I9:J9) -> 10 | L9: =K9/H9 -> 1 | M9: =IF(AND($B$2="WBK",L9>=60%),"OK",IF(AND($B$2="WBBM",L9>=75%),"OK","Tidak Lulus")) -> OK
A10: 74 | D10: 5. | E10: PENGUATAN PENGAWASAN | H10: 15 | I10: =Jawaban!O73 -> 7.5 | J10: =Jawaban!O164 -> 7.5 | K10: =SUM(I10:J10) -> 15 | L10: =K10/H10 -> 1 | M10: =IF(AND($B$2="WBK",L10>=60%),"OK",IF(AND($B$2="WBBM",L10>=75%),"OK","Tidak Lulus")) -> OK
A11: 102 | D11: 6. | E11: PENINGKATAN KUALITAS PELAYANAN PUBLIK | H11: 10 | I11: =Jawaban!O97 -> 5 | J11: =Jawaban!O187 -> 5 | K11: =SUM(I11:J11) -> 10 | L11: =K11/H11 -> 1 | M11: =IF(AND($B$2="WBK",L11>=60%),"OK",IF(AND($B$2="WBBM",L11>=75%),"OK","Tidak Lulus")) -> OK
A12: 211 | B12: TOTAL PENGUNGKIT | K12: =SUM(K6:K11) -> 60 | L12: =K12/H5 -> 1 | M12: =IF(AND($B$2="WBK",K12>=40),"OK",IF(AND($B$2="WBBM",K12>=48),"OK","Tidak Lulus")) -> OK
A13: 212
A14: 214 | B14: B. | C14: HASIL | H14: 40
A15: 215 | C15: I. | D15: BIROKRASI YANG BERSIH DAN AKUNTABEL | H15: 22.5 | K15: =SUM(K16:K17) -> 22.5 | L15: =K15/H15 -> 1 | M15: =IF(AND($B$2="WBK",K15>=18.25),"OK",IF(AND($B$2="WBBM",K15>=19.5),"OK","Tidak Lulus")) -> OK
A16: 216 | D16: a | E16: Nilai Survey Persepsi Korupsi (Survei Eksternal : Indeks Persepsi Anti Korupsi/ IPAK) | H16: 17.5 | K16: =Jawaban!O199 -> 17.5 | L16: =K16/H16 -> 1 | M16: =IF(AND($B$2="WBK",K16>=15.75),"OK",IF(AND($B$2="WBBM",K16>=15.75),"OK","Tidak Lulus")) -> OK
A17: 218 | D17: b | E17: Capaian Kinerja Lebih Baik dari pada Capaian Kinerja Sebelumnya | H17: 5 | K17: =Jawaban!O200 -> 5 | L17: =K17/H17 -> 1 | M17: =IF(AND($B$2="WBK",K17>=2.5),"OK",IF(AND($B$2="WBBM",K17>=3.75),"OK","Tidak Lulus")) -> OK
A18: 219 | C18: II. | D18: PELAYANAN PUBLIK YANG PRIMA | H18: 17.5 | K18: =SUM(K19) -> 17.5 | L18: =K18/H18 -> 1
A19: 221 | D19: - | E19: Nilai Persepsi Kualitas Pelayanan (Survei Eksternal : Indeks Persepsi Kualitas Pelayanan Publik / IPKP) | H19: 17.5 | K19: =Jawaban!O202 -> 17.5 | L19: =K19/H19 -> 1 | M19: =IF(AND($B$2="WBK",K19>=14),"OK",IF(AND($B$2="WBBM",K19>=15.75),"OK","Tidak Lulus")) -> OK
A20: 222 | B20: TOTAL HASIL | K20: =SUM(K15,K18) -> 40 | L20: =K20/H14 -> 1
A21: 223
B22: NILAI EVALUASI REFORMASI BIROKRASI | K22: =Jawaban!O204 -> 100 | M22: =IF(AND($B$2="WBK",K22>=75),"OK",IF(AND($B$2="WBBM",K22>=85),"OK","Tidak Lulus")) -> OK

Sheet Jawaban
A1: 1 | B1: Penilaian | H1: Bobot | I1: Kriteria Nilai | J1: Pilihan Jawaban | K1: Jawaban Unit | L1: Catatan/Keterangan/Penjelasan Unit | M1: Bukti Dukung Unit | N1: Jawaban TPI | O1: Nilai | P1: % | Q1: Catatan/Keterangan/Penjelasan Evaluasi TPI | R1: Link Google Drive Data Dukung B03 | S1: Link Google Drive Data Dukung B06 | T1: Link Google Drive Data Dukung B09 | U1: Link Google Drive Data Dukung B12 | V1: Link Google Drive Data Dukung B12 Tahun Sebelumnya
A2: 3 | B2: A. | C2: PENGUNGKIT | H2: 60 | O2: =O195 -> 60 | P2: =O2/H2 -> 1
A3: 4 | C3: I. | D3: PEMENUHAN | H3: 30 | O3: =SUM(O4,O21,O34,O59,O73,O97) -> 30 | P3: =O3/H3 -> 1
A4: 5 | D4: 1. | E4: MANAJEMEN PERUBAHAN | H4: 4 | O4: =SUM(O5,O8,O12,O16) -> 4 | P4: =O4/H4 -> 1
A5: 6 | E5: i. | F5: Penyusunan Tim Kerja | H5: 0.5 | O5: =AVERAGE(O6:O7)*H5 -> 0.5 | P5: =O5/H5 -> 1
A6: 7 | F6: a. | G6: Unit kerja telah membentuk tim untuk melakukan pembangunan Zona Integritas. | I6: Ya, jika Tim telah dibentuk di dalam unit kerja. | J6: Ya/Tidak | K6: Ya | M6: 1. SK Tim Kerja Pembangunan ZI Menuju WBK/WBBM; 2. SK Perubahan atas SK Tim Kerja Pembangunan ZI Menuju WBK/WBBM (jika ada); 3. SK Perubahan (Kedua, Ketiga, dst) atas SK Tim Kerja Pembangunan ZI Menuju WBK/WBBM (jika ada). Keterangan: Apabila ada penggantian Kepala Satuan Kerja ditambahkan dengan SK Tim Baru. | N6: Ya | O6: =IF(J6="Ya/Tidak",IF(N6="Ya",1,IF(N6="Tidak",0,"Blm Diisi")),IF(J6="A/B/C",IF(N6="A",1,IF(N6="B",0.5,IF(N6="C",0,"Blm Diisi"))),IF(J6="A/B/C/D",IF(N6="A",1,IF(N6="B",0.67,IF(N6="C",0.33,IF(N6="D",0,"Blm Diisi")))),IF(J6="A/B/C/D/E",IF(N6="A",1,IF(N6="B",0.75,IF(N6="C",0.5,IF(N6="D",0.25,IF(N6="E",0,"Blm Diisi"))))),IF(J6="%",IF(N6="","Blm Diisi",N6),IF(J6="Jumlah",IF(N6="","Blm Diisi",""),IF(J6="Rupiah",IF(N6="","Blm Diisi",""),IF(J6="","","-")))))))) -> 1 | R6: a. Unit kerja telah membentuk tim untuk melakukan pembangunan Zona Integritas.
A7: 8 | F7: b. | G7: Penentuan anggota Tim dipilih melalui prosedur/mekanisme yang jelas. | I7: a. Jika dengan prosedur/mekanisme yang jelas dan mewakili seluruh unsur dalam unit kerja. b. Jika sebagian menggunakan prosedur yang mewakili sebagian besar unsur dalam unit kerja. c. Jika tidak di seleksi. | J7: A/B/C | K7: A | M7: Dokumen Kegiatan Rapat Tim Kerja: 1. undangan rapat; 2. daftar hadir; 3. notula dan dokumentasi foto; 4. SK Tim Seleksi; 5. berita acara; 6. laporan pelaksanaan seleksi anggota tim kerja; 7. Daftar Riwayat Hidup dan Daftar Riwayat Pekerjaan (diunduh melalui aplikasi STAR ASN KemenIMIPAS). | N7: A | O7: =IF(J7="Ya/Tidak",IF(N7="Ya",1,IF(N7="Tidak",0,"Blm Diisi")),IF(J7="A/B/C",IF(N7="A",1,IF(N7="B",0.5,IF(N7="C",0,"Blm Diisi"))),IF(J7="A/B/C/D",IF(N7="A",1,IF(N7="B",0.67,IF(N7="C",0.33,IF(N7="D",0,"Blm Diisi")))),IF(J7="A/B/C/D/E",IF(N7="A",1,IF(N7="B",0.75,IF(N7="C",0.5,IF(N7="D",0.25,IF(N7="E",0,"Blm Diisi"))))),IF(J7="%",IF(N7="","Blm Diisi",N7),IF(J7="Jumlah",IF(N7="","Blm Diisi",""),IF(J7="Rupiah",IF(N7="","Blm Diisi",""),IF(J7="","","-")))))))) -> 1 | R7: b. Penentuan anggota Tim dipilih melalui prosedur/mekanisme yang jelas.
A8: 9 | E8: ii. | F8: Rencana Pembangunan Zona Integritas | H8: 1 | O8: =AVERAGE(O9:O11)*H8 -> 1 | P8: =O8/H8 -> 1
A9: 10 | F9: a. | G9: Terdapat dokumen rencana kerja pembangunan Zona Integritas menuju WBK/WBBM. | I9: Ya, jika memiliki rencana kerja pembangunan Zona Integritas. | J9: Ya/Tidak | K9: Ya | M9: Dokumen kegiatan Rapat Penetapan Rencana Kerja dan Target Prioritas: 1. Undangan rapat; 2. daftar hadir; 3. notula dan dokumentasi foto; 4. laporan kegiatan rapat penetapan Rencana Kerja; 5. SK tentang Rencana Kerja dan Target Prioritas Pembangunan ZI menuju WBK/WBBM satuan kerja yang ditandatangani oleh Kepala Satuan Kerja. | N9: Ya | O9: =IF(J9="Ya/Tidak",IF(N9="Ya",1,IF(N9="Tidak",0,"Blm Diisi")),IF(J9="A/B/C",IF(N9="A",1,IF(N9="B",0.5,IF(N9="C",0,"Blm Diisi"))),IF(J9="A/B/C/D",IF(N9="A",1,IF(N9="B",0.67,IF(N9="C",0.33,IF(N9="D",0,"Blm Diisi")))),IF(J9="A/B/C/D/E",IF(N9="A",1,IF(N9="B",0.75,IF(N9="C",0.5,IF(N9="D",0.25,IF(N9="E",0,"Blm Diisi"))))),IF(J9="%",IF(N9="","Blm Diisi",N9),IF(J9="Jumlah",IF(N9="","Blm Diisi",""),IF(J9="Rupiah",IF(N9="","Blm Diisi",""),IF(J9="","","-")))))))) -> 1 | R9: a. Terdapat dokumen rencana kerja pembangunan Zona Integritas menuju WBK/WBBM.
A10: 11 | F10: b. | G10: Dalam dokumen pembangunan terdapat target-target prioritas yang relevan dengan tujuan pembangunan WBK/WBBM. | I10: a. Jika semua target-target prioritas relevan dengan tujuan pembangunan WBK/WBBM. b. Jika sebagian target-target prioritas relevan dengan tujuan pembangunan WBK/WBBM. c. Jika tidak ada target-target prioritas yang relevan dengan tujuan pembangunan WBK/WBBM. | J10: A/B/C | K10: A | M10: Dokumen kegiatan rapat penetapan Rencana Kerja dan Target Prioritas: 1. undangan rapat; 2. daftar hadir; 3. notula dan dokumentasi foto; 4. laporan kegiatan rapat penetapan Rencana Kerja; 5. SK tentang Rencana Kerja dan Target Prioritas Pembangunan ZI menuju WBK/WBBM satuan kerja yang ditandatangani oleh Kepala Satuan Kerja. | N10: A | O10: =IF(J10="Ya/Tidak",IF(N10="Ya",1,IF(N10="Tidak",0,"Blm Diisi")),IF(J10="A/B/C",IF(N10="A",1,IF(N10="B",0.5,IF(N10="C",0,"Blm Diisi"))),IF(J10="A/B/C/D",IF(N10="A",1,IF(N10="B",0.67,IF(N10="C",0.33,IF(N10="D",0,"Blm Diisi")))),IF(J10="A/B/C/D/E",IF(N10="A",1,IF(N10="B",0.75,IF(N10="C",0.5,IF(N10="D",0.25,IF(N10="E",0,"Blm Diisi"))))),IF(J10="%",IF(N10="","Blm Diisi",N10),IF(J10="Jumlah",IF(N10="","Blm Diisi",""),IF(J10="Rupiah",IF(N10="","Blm Diisi",""),IF(J10="","","-")))))))) -> 1 | R10: b. Dalam dokumen pembangunan terdapat target-target prioritas yang relevan dengan tujuan pembangunan WBK/WBBM.
A11: 12 | F11: c. | G11: Terdapat mekanisme atau media untuk mensosialisasikan pembangunan WBK/WBBM. | I11: a. Jika telah dilakukan pengelolaan media/ aktivitas interaktif yang efektif untuk menginformasikan pembangunan ZI kepada internal dan stakeholder secara berkala. b. Jika pengelolaan media/aktivitas interaktif dilakukan secara terbatas dan tidak secara berkala. c. Jika pengelolaan media/aktivitas interaktif belum dilakukan. | J11: A/B/C | K11: A | M11: B03: 1. Dokumen laporan pelaksanaan kegiatan Pencanangan Zona Integritas, yaitu: a. Kegiatan Ekternal Pencanangan Zona Integritas melampirkan Foto, Laporan Kegiatan dan Press release. b. Kegiatan Internal 1) Dokumen Perjanjian Kinerja; 2) Dokumen Penandatanganan Pakta Integritas antara Kepala Satuan Kerja dengan jajaran struktural dibawahnya; 3) Dokumen Pakta Integritas antara jajaran Struktural dalam satuan kerja dengan pegawai. B03, B06, B09, B12: 2. Dokumen kegiatan sosialisasi Kepala satuan kerja/ internalisasi/pembinaan/pendampingan terkait Pembangunan ZI menuju WBK/WBBM: a. undangan; b. daftar hadir; c. notula dan dokumentasi foto; d. laporan kegiatan. 3. Dokumen sosialisasi kepada masyarakat: (minimal 3 dari data dukung di bawah) a. Capture Banner/spanduk/himbauan/brosur; b. Capture Website; c. Capture Media Sosial; d. Capture Media elektronik; e. Capture Media cetak; f. Capture Media TV; g. Laporan kegiatan sosialisasi kepada masyarakat. | N11: A | O11: =IF(J11="Ya/Tidak",IF(N11="Ya",1,IF(N11="Tidak",0,"Blm Diisi")),IF(J11="A/B/C",IF(N11="A",1,IF(N11="B",0.5,IF(N11="C",0,"Blm Diisi"))),IF(J11="A/B/C/D",IF(N11="A",1,IF(N11="B",0.67,IF(N11="C",0.33,IF(N11="D",0,"Blm Diisi")))),IF(J11="A/B/C/D/E",IF(N11="A",1,IF(N11="B",0.75,IF(N11="C",0.5,IF(N11="D",0.25,IF(N11="E",0,"Blm Diisi"))))),IF(J11="%",IF(N11="","Blm Diisi",N11),IF(J11="Jumlah",IF(N11="","Blm Diisi",""),IF(J11="Rupiah",IF(N11="","Blm Diisi",""),IF(J11="","","-")))))))) -> 1 | R11: c. Terdapat mekanisme atau media untuk mensosialisasikan pembangunan WBK/WBBM.
A12: 13 | E12: iii. | F12: Pemantauan dan Evaluasi Pembangunan WBK/WBBM | H12: 1 | O12: =AVERAGE(O13:O15)*H12 -> 1 | P12: =O12/H12 -> 1
A13: 14 | F13: a. | G13: Seluruh kegiatan pembangunan sudah dilaksanakan sesuai dengan rencana. | I13: a. Jika semua kegiatan pembangunan telah dilaksanakan sesuai dengan rencana. b. Jika sebagian besar kegiatan pembangunan telah dilaksanakan sesuai dengan rencana. c. Jika sebagian kecil kegiatan pembangunan telah dilaksanakan sesuai dengan rencana. d. Jika belum ada kegiatan pembangunan yang dilakukan sesuai dengan rencana. | J13: A/B/C/D | K13: A | M13: Dokumen kegiatan rapat pelaksanaan Rencana Aksi dan Target Prioritas oleh Tim Kerja: 1. undangan rapat; 2. daftar hadir; 3. notula dan dokumentasi foto; 4. laporan kegiatan kegiatan pembangunan ZI berdasarkan Rencana Aksi dan Target Prioritas. | N13: A | O13: =IF(J13="Ya/Tidak",IF(N13="Ya",1,IF(N13="Tidak",0,"Blm Diisi")),IF(J13="A/B/C",IF(N13="A",1,IF(N13="B",0.5,IF(N13="C",0,"Blm Diisi"))),IF(J13="A/B/C/D",IF(N13="A",1,IF(N13="B",0.67,IF(N13="C",0.33,IF(N13="D",0,"Blm Diisi")))),IF(J13="A/B/C/D/E",IF(N13="A",1,IF(N13="B",0.75,IF(N13="C",0.5,IF(N13="D",0.25,IF(N13="E",0,"Blm Diisi"))))),IF(J13="%",IF(N13="","Blm Diisi",N13),IF(J13="Jumlah",IF(N13="","Blm Diisi",""),IF(J13="Rupiah",IF(N13="","Blm Diisi",""),IF(J13="","","-")))))))) -> 1 | R13: a. Seluruh kegiatan pembangunan sudah dilaksanakan sesuai dengan rencana.
A14: 15 | F14: b. | G14: Terdapat monitoring dan evaluasi terhadap pembangunan Zona Integritas. | I14: a. Jika monitoring dan evaluasi melibatkan pimpinan dan dilakukan secara berkala. b. Jika monitoring dan evaluasi melibatkan pimpinan tetapi tidak secara berkala. c. Jika monitoring dan evaluasi tidak melibatkan pimpinan dan tidak secara berkala. d. Jika tidak terdapat monitoring dan evaluasi terhadap pembangunan zona integritas. | J14: A/B/C/D | K14: A | M14: Dokumen kegiatan penyusunan laporan hasil monitoring dan evaluasi: 1. undangan rapat; 2. daftar hadir; 3. notula dan dokumentasi foto; 4. laporan hasil monitoring dan evaluasi triwulan. | N14: A | O14: =IF(J14="Ya/Tidak",IF(N14="Ya",1,IF(N14="Tidak",0,"Blm Diisi")),IF(J14="A/B/C",IF(N14="A",1,IF(N14="B",0.5,IF(N14="C",0,"Blm Diisi"))),IF(J14="A/B/C/D",IF(N14="A",1,IF(N14="B",0.67,IF(N14="C",0.33,IF(N14="D",0,"Blm Diisi")))),IF(J14="A/B/C/D/E",IF(N14="A",1,IF(N14="B",0.75,IF(N14="C",0.5,IF(N14="D",0.25,IF(N14="E",0,"Blm Diisi"))))),IF(J14="%",IF(N14="","Blm Diisi",N14),IF(J14="Jumlah",IF(N14="","Blm Diisi",""),IF(J14="Rupiah",IF(N14="","Blm Diisi",""),IF(J14="","","-")))))))) -> 1 | R14: b. Terdapat monitoring dan evaluasi terhadap pembangunan Zona Integritas.
A15: 16 | F15: c. | G15: Hasil Monitoring dan Evaluasi telah ditindaklanjuti. | I15: a. Jika semua catatan/rekomendasi hasil monitoring dan evaluasi tim internal atas persiapan dan pelaksanaan kegiatan Unit WBK/WBBM telah ditindaklanjuti. b. Jika sebagian besar catatan/rekomendasi hasil monitoring danevaluasi tim internal atas persiapan dan pelaksanaan kegiatan Unit WBK/WBBM telah ditindaklanjuti. c. Jika sebagian kecil catatan/rekomendasi hasil monitoring dan evaluasi tim internal atas persiapan dan pelaksanaan kegiatan Unit WBK/WBBM telah ditindaklanjuti. d. Jika catatan/rekomendasi hasil monitoring dan evaluasi tim internal atas persiapan dan pelaksanaan kegiatan Unit WBK/WBBM belum ditindaklanjuti. | J15: A/B/C/D | K15: A | M15: Dokumen kegiatan penyusunan laporan tindak lanjut hasil monitoring dan evaluasi: 1. undangan rapat; 2. daftar hadir; 3. notula dan dokumentasi foto; 4. laporan tindak lanjut hasil monitoring dan evaluasi. | N15: A | O15: =IF(J15="Ya/Tidak",IF(N15="Ya",1,IF(N15="Tidak",0,"Blm Diisi")),IF(J15="A/B/C",IF(N15="A",1,IF(N15="B",0.5,IF(N15="C",0,"Blm Diisi"))),IF(J15="A/B/C/D",IF(N15="A",1,IF(N15="B",0.67,IF(N15="C",0.33,IF(N15="D",0,"Blm Diisi")))),IF(J15="A/B/C/D/E",IF(N15="A",1,IF(N15="B",0.75,IF(N15="C",0.5,IF(N15="D",0.25,IF(N15="E",0,"Blm Diisi"))))),IF(J15="%",IF(N15="","Blm Diisi",N15),IF(J15="Jumlah",IF(N15="","Blm Diisi",""),IF(J15="Rupiah",IF(N15="","Blm Diisi",""),IF(J15="","","-")))))))) -> 1 | R15: c. Hasil Monitoring dan Evaluasi telah ditindaklanjuti.
A16: 17 | E16: iv. | F16: Perubahan pola pikir dan budaya kerja | H16: 1.5 | O16: =AVERAGE(O17:O20)*H16 -> 1.5 | P16: =O16/H16 -> 1
A17: 18 | F17: a. | G17: Pimpinan berperan sebagai role model dalam pelaksanaan Pembangunan WBK/WBBM. | I17: ya, jika pimpinan menjadi contoh pelaksanaan nilai-nilai organisasi. | J17: Ya/Tidak | K17: Ya | M17: 1. Arahan kepala satuan kerja terkait pembangunan ZI dan nilai dasar/core value: a. undangan; b. daftar hadir; c. notula; d. laporan. 2. Absensi pimpinan Satker dan pejabat struktural (Misal sampling: Bulan Januari, Februari, dan Maret) (data dukung diperbaharui tiap triwulan). 3. Dokumentasi pimpinan/pejabat struktural menjadi Pembina apel dan pembina upacara. (data dukung diperbaharui tiap triwulan). 4. Dokumen Jurnal Harian Pimpinan dan Pejabat Struktural (Sampling: Bulan Januari, Februari, dan Maret) (data dukung diperbaharui tiap triwulan): a. Untuk satuan kerja Eselon I, daftar hadir dan jurnal harian yang dibutuhkan sampai kepada Jabatan Struktural Eselon I, II, dan III; b. Untuk satuan kerja Eselon II, daftar hadir dan jurnal harian yang dibutuhkan sampai kepada Jabatan Struktural Eselon II dan III; c. Untuk satuan kerja Eselon III, daftar hadir dan jurnal harian yang dibutuhkan sampai kepada Jabatan Struktural Eselon III dan IV. | N17: Ya | O17: =IF(J17="Ya/Tidak",IF(N17="Ya",1,IF(N17="Tidak",0,"Blm Diisi")),IF(J17="A/B/C",IF(N17="A",1,IF(N17="B",0.5,IF(N17="C",0,"Blm Diisi"))),IF(J17="A/B/C/D",IF(N17="A",1,IF(N17="B",0.67,IF(N17="C",0.33,IF(N17="D",0,"Blm Diisi")))),IF(J17="A/B/C/D/E",IF(N17="A",1,IF(N17="B",0.75,IF(N17="C",0.5,IF(N17="D",0.25,IF(N17="E",0,"Blm Diisi"))))),IF(J17="%",IF(N17="","Blm Diisi",N17),IF(J17="Jumlah",IF(N17="","Blm Diisi",""),IF(J17="Rupiah",IF(N17="","Blm Diisi",""),IF(J17="","","-")))))))) -> 1 | R17: a. Pimpinan berperan sebagai role model dalam pelaksanaan Pembangunan WBK/WBBM.
A18: 19 | F18: b. | G18: Sudah ditetapkan agen perubahan. | I18: a. Jika agen perubahan telah ditetapkan dan berkontribusi terhadap perubahan pada unit kerjanya. b. Jika agen perubahan telah ditetapkan namun belum berkontribusi terhadap perubahan pada unit kerjanya. c. Jika belum terdapat agen perubahan. | J18: A/B/C | K18: A | M18: Dokumen pelaksanaan kegiatan penetapan Agen Perubahan: 1. undangan; 2. daftar hadir; 3. notula dan dokumentasi foto; 4. Riwayat Hidup dan rekam jejak agen perubahan; 5. SK Agen Perubahan yang ditetapkan oleh Kepala Satuan Kerja. Keterangan : Masing-masing Agen Perubahan yang ditunjuk harus memiliki prestasi/kontribusi dalam pembangunan ZI dan satu agen perubahan minimal memiliki satu produk perubahan, yang terintegrasi dengan Sistem Manajemen pada satuan kerja (tidak termasuk jingle, maskot, jargon). | N18: A | O18: =IF(J18="Ya/Tidak",IF(N18="Ya",1,IF(N18="Tidak",0,"Blm Diisi")),IF(J18="A/B/C",IF(N18="A",1,IF(N18="B",0.5,IF(N18="C",0,"Blm Diisi"))),IF(J18="A/B/C/D",IF(N18="A",1,IF(N18="B",0.67,IF(N18="C",0.33,IF(N18="D",0,"Blm Diisi")))),IF(J18="A/B/C/D/E",IF(N18="A",1,IF(N18="B",0.75,IF(N18="C",0.5,IF(N18="D",0.25,IF(N18="E",0,"Blm Diisi"))))),IF(J18="%",IF(N18="","Blm Diisi",N18),IF(J18="Jumlah",IF(N18="","Blm Diisi",""),IF(J18="Rupiah",IF(N18="","Blm Diisi",""),IF(J18="","","-")))))))) -> 1 | R18: b. Sudah ditetapkan agen perubahan.
A19: 20 | F19: c. | G19: Telah dibangun budaya kerja dan pola pikir di lingkungan organisasi. | I19: a. Jika telah dilakukan upaya pembangunan budaya kerja dan pola pikir dan mampu mengurangi resistensi atas perubahan. b. Jika telah dilakukan upaya pembangunan budaya kerja dan pola pikir tapi masih terdapat resistensi atas perubahan. c. Jika belum terdapat upaya pembangunan budaya kerja dan pola pikir. | J19: A/B/C | K19: A | M19: B03: 1. Dokumen Laporan Pelaksanaan Kegiatan Pelatihan budaya kerja atau BerAKHLAK (Kegiatan dapat dilakukan oleh internal satuan kerja. Contoh: Workshop, in House Training) 2. Dokumen laporan pelaksanaan kegiatan penerapan budaya kerja berikut dokumentasinya. B03, B06, B09, B12: 3. Dokumentasi pegawai yang menerima reward dan punishment. Contoh: a. Penghargaan/Piagam terhadap pegawai terbaik/ teladan atas kehadiran dan kinerja; dan b. SK Hukdis/Usulan Penjatuhan Hukdis dan BAP. (Jika tidak terdapat hukdis menggunakan surat keterangan kasatker yang menyatakan bahwa tidak terdapat pegawai yang sedang dalam proses atau menjalani hukdis pada satuan kerja) | N19: A | O19: =IF(J19="Ya/Tidak",IF(N19="Ya",1,IF(N19="Tidak",0,"Blm Diisi")),IF(J19="A/B/C",IF(N19="A",1,IF(N19="B",0.5,IF(N19="C",0,"Blm Diisi"))),IF(J19="A/B/C/D",IF(N19="A",1,IF(N19="B",0.67,IF(N19="C",0.33,IF(N19="D",0,"Blm Diisi")))),IF(J19="A/B/C/D/E",IF(N19="A",1,IF(N19="B",0.75,IF(N19="C",0.5,IF(N19="D",0.25,IF(N19="E",0,"Blm Diisi"))))),IF(J19="%",IF(N19="","Blm Diisi",N19),IF(J19="Jumlah",IF(N19="","Blm Diisi",""),IF(J19="Rupiah",IF(N19="","Blm Diisi",""),IF(J19="","","-")))))))) -> 1 | R19: c. Telah dibangun budaya kerja dan pola pikir di lingkungan organisasi.
A20: 21 | F20: d. | G20: Anggota organisasi terlibat dalam pembangunan Zona Integritas menuju WBK/WBBM. | I20: a. Jika semua anggota terlibat dalam pembangunan Zona Integritas menuju WBK/ WBBM dan usulan-usulan dari anggota diakomodasikan dalam keputusan. b. Jika sebagian besar anggota terlibat dalam pembangunan Zona Integritas menuju WBK/ WBBM. c. Jika sebagian kecil anggota terlibat dalam pembangunan Zona Integritas menuju WBK/ WBBM. d. Jika belum ada anggota terlibat dalam pembangunan Zona Integritas menuju WBK/ WBBM. | J20: A/B/C/D | K20: A | M20: B03: 1. Dokumen kegiatan yang melibatkan seluruh pegawai dalam pembangunan ZI menuju WBK/WBBM seperti rapat pembuatan jingle satker, rapat pembuatan motto atau slogan satker, yel-yel, maskot dan jargon, kegiatan pemasangan banner/poster dan coffee briefing/coffee morning: a) undangan; b) daftar hadir; c) notula yang menjelaskan keterlibatan pegawai dalam memberikan usulan seperti usulan yel-yel, jargon, maskot dll. dan dokumentasi foto; d) Laporan. B03, B06, B09, B12: 2. Dokumen laporan kegiatan yang melibatkan seluruh pegawai seperti apel pagi dan apel sore, jumat olahraga, dan kegiatan rohani. | N20: A | O20: =IF(J20="Ya/Tidak",IF(N20="Ya",1,IF(N20="Tidak",0,"Blm Diisi")),IF(J20="A/B/C",IF(N20="A",1,IF(N20="B",0.5,IF(N20="C",0,"Blm Diisi"))),IF(J20="A/B/C/D",IF(N20="A",1,IF(N20="B",0.67,IF(N20="C",0.33,IF(N20="D",0,"Blm Diisi")))),IF(J20="A/B/C/D/E",IF(N20="A",1,IF(N20="B",0.75,IF(N20="C",0.5,IF(N20="D",0.25,IF(N20="E",0,"Blm Diisi"))))),IF(J20="%",IF(N20="","Blm Diisi",N20),IF(J20="Jumlah",IF(N20="","Blm Diisi",""),IF(J20="Rupiah",IF(N20="","Blm Diisi",""),IF(J20="","","-")))))))) -> 1 | R20: d. Anggota organisasi terlibat dalam pembangunan Zona Integritas menuju WBK/WBBM.
A21: 22 | D21: 2. | E21: PENATAAN TATALAKSANA | H21: 3.5 | O21: =SUM(O22,O26,O31) -> 3.5 | P21: =O21/H21 -> 1
A22: 23 | E22: i. | F22: Prosedur Operasional Tetap (SOP) Kegiatan Utama | H22: 1 | O22: =AVERAGE(O23:O25)*H22 -> 1 | P22: =O22/H22 -> 1
A23: 24 | F23: a. | G23: SOP mengacu pada peta proses bisnis instansi. | I23: a. Jika semua SOP unit telah mengacu peta proses bisnis dan juga melakukan inovasi yang selaras. b. Jika semua SOP unit telah mengacu peta proses bisnis. c. Jika sebagian SOP unit telah mengacu peta proses bisnis. d. Jika belum terdapat SOP unit yang mengacu peta proses bisnis. | J23: A/B/C/D | K23: A | M23: 1. Dokumen Peta Bisnis Instansi (Kementerian). 2. Dokumen SOP Pusat/Unit Eselon I. 3. Dokumen SOP Flowchart dan Grafik Satuan Kerja. 4. Dokumen SOP Inovasi Flowchart dan Grafik (Ditetapkan oleh Ka. UPT/Satker). Penyusunan SOP mengacu kepada format yang ditetapkan dalam Permenpanrb Nomor 35 Tahun 2012 tentang Pedoman Penyusunan Standar Operasional Prosedur Administrasi Pemerintahan. Keterangan: Apabila Dokumen Peta Bisnis Instansi (Kementerian) belum tersedia, data dukung dapat dipenuhi dengan melampirkan: a. draf Dokumen Peta Bisnis Instansi; dan b. Surat Pernyataan Kepala Biro Sumber Daya Manusia Organisasi dan Ketatalaksanaan yang menyatakan bahwa Dokumen Peta Bisnis belum tersedia serta dilampirkan juga dengan timeline penyelesaiannya. | N23: A | O23: =IF(J23="Ya/Tidak",IF(N23="Ya",1,IF(N23="Tidak",0,"Blm Diisi")),IF(J23="A/B/C",IF(N23="A",1,IF(N23="B",0.5,IF(N23="C",0,"Blm Diisi"))),IF(J23="A/B/C/D",IF(N23="A",1,IF(N23="B",0.67,IF(N23="C",0.33,IF(N23="D",0,"Blm Diisi")))),IF(J23="A/B/C/D/E",IF(N23="A",1,IF(N23="B",0.75,IF(N23="C",0.5,IF(N23="D",0.25,IF(N23="E",0,"Blm Diisi"))))),IF(J23="%",IF(N23="","Blm Diisi",N23),IF(J23="Jumlah",IF(N23="","Blm Diisi",""),IF(J23="Rupiah",IF(N23="","Blm Diisi",""),IF(J23="","","-")))))))) -> 1 | R23: a. SOP mengacu pada peta proses bisnis instansi.
A24: 25 | F24: b. | G24: Prosedur operasional tetap (SOP) telah diterapkan. | I24: a. Jika unit telah menerapkan seluruh SOP yang ditetapkan organisasi dan juga melakukan inovasi pada SOP yang diterapkan. b. Jika unit telah menerapkan seluruh SOP yang ditetapkan organisasi. c. Jika unit telah menerapkan sebagian besar SOP yang ditetapkan organisasi. d. Jika unit telah menerapkan sebagian kecil SOP yang ditetapkan organisasi. e. Jika unit belum menerapkan SOP yang telah ditetapkan organisasi. | J24: A/B/C/D/E | K24: A | M24: 1. Kepala Satuan Kerja menerbitkan kembali SOP dari Unit Eselon I/Kementerian dalam bentuk SK Kepala Satuan Kerja serta melakukan inovasi terkait dengan pelayanan yang dilaksanakan di satuan kerja. 2. Dokumentasi pemasangan/informasi tentang alur atau prosedur layanan. | N24: A | O24: =IF(J24="Ya/Tidak",IF(N24="Ya",1,IF(N24="Tidak",0,"Blm Diisi")),IF(J24="A/B/C",IF(N24="A",1,IF(N24="B",0.5,IF(N24="C",0,"Blm Diisi"))),IF(J24="A/B/C/D",IF(N24="A",1,IF(N24="B",0.67,IF(N24="C",0.33,IF(N24="D",0,"Blm Diisi")))),IF(J24="A/B/C/D/E",IF(N24="A",1,IF(N24="B",0.75,IF(N24="C",0.5,IF(N24="D",0.25,IF(N24="E",0,"Blm Diisi"))))),IF(J24="%",IF(N24="","Blm Diisi",N24),IF(J24="Jumlah",IF(N24="","Blm Diisi",""),IF(J24="Rupiah",IF(N24="","Blm Diisi",""),IF(J24="","","-")))))))) -> 1 | R24: b. Prosedur operasional tetap (SOP) telah diterapkan.
A25: 26 | F25: c. | G25: Prosedur operasional tetap (SOP) telah dievaluasi. | I25: a. Jika seluruh SOP utama telah dievaluasi dan telah ditindaklanjuti berupa perbaikan SOP atau usulan perbaikan SOP. b. Jika sebagian besar SOP utama telah dievaluasi dan telah ditindaklanjuti berupa perbaikan SOP atau usulan perbaikan SOP. c. Jika sebagian besar SOP utama telah dievaluasi tetapi belum ditindaklanjuti. d. Jika sebagian kecil SOP utama telah dievaluasi. e. Jika SOP belum pernah dievaluasi. | J25: A/B/C/D/E | K25: A | M25: Dokumen monitoring dan evaluasi penerapan SOP satuan kerja: 1. undangan; 2. daftar hadir; 3. notula dan dokumentasi kegiatan; 4. laporan hasil monitoring dan evaluasi penerapan SOP berisi Matriks perubahan SOP semula dan SOP Perubahan atau usulan perbaikan SOP. | N25: A | O25: =IF(J25="Ya/Tidak",IF(N25="Ya",1,IF(N25="Tidak",0,"Blm Diisi")),IF(J25="A/B/C",IF(N25="A",1,IF(N25="B",0.5,IF(N25="C",0,"Blm Diisi"))),IF(J25="A/B/C/D",IF(N25="A",1,IF(N25="B",0.67,IF(N25="C",0.33,IF(N25="D",0,"Blm Diisi")))),IF(J25="A/B/C/D/E",IF(N25="A",1,IF(N25="B",0.75,IF(N25="C",0.5,IF(N25="D",0.25,IF(N25="E",0,"Blm Diisi"))))),IF(J25="%",IF(N25="","Blm Diisi",N25),IF(J25="Jumlah",IF(N25="","Blm Diisi",""),IF(J25="Rupiah",IF(N25="","Blm Diisi",""),IF(J25="","","-")))))))) -> 1 | R25: c. Prosedur operasional tetap (SOP) telah dievaluasi.
A26: 27 | E26: ii. | F26: Sistem Pemerintahan Berbasis Elektronik (SPBE) | H26: 2 | O26: =AVERAGE(O27:O30)*H26 -> 2 | P26: =O26/H26 -> 1
A27: 28 | F27: a. | G27: Sistem pengukuran kinerja unit sudah menggunakan teknologi informasi. | I27: a. Jika unit memiliki sistem pengukuran kinerja (e-performance/e-sakip) yang menggunakan teknologi informasi dan juga melakukan inovasi. b. Jika unit memiliki sistem pengukuran kinerja (e-performance/e-sakip) yang menggunakan teknologi informasi. c. Jika belum memiliki sistem pengukuran kinerja (e-performance/e-sakip) yang menggunakan teknologi informasi. | J27: A/B/C | K27: A | M27: 1. Capture penggunaan teknologi/aplikasi pengukuran kinerja. 2. Capture Inovasi terkait sistem pengukuran kinerja pada satuan kerja. (jika ada) 3. Jurnal Harian pegawai yang ditandatangani oleh pegawai yang bersangkutan dan atasan langsung. | N27: A | O27: =IF(J27="Ya/Tidak",IF(N27="Ya",1,IF(N27="Tidak",0,"Blm Diisi")),IF(J27="A/B/C",IF(N27="A",1,IF(N27="B",0.5,IF(N27="C",0,"Blm Diisi"))),IF(J27="A/B/C/D",IF(N27="A",1,IF(N27="B",0.67,IF(N27="C",0.33,IF(N27="D",0,"Blm Diisi")))),IF(J27="A/B/C/D/E",IF(N27="A",1,IF(N27="B",0.75,IF(N27="C",0.5,IF(N27="D",0.25,IF(N27="E",0,"Blm Diisi"))))),IF(J27="%",IF(N27="","Blm Diisi",N27),IF(J27="Jumlah",IF(N27="","Blm Diisi",""),IF(J27="Rupiah",IF(N27="","Blm Diisi",""),IF(J27="","","-")))))))) -> 1 | R27: a. Sistem pengukuran kinerja unit sudah menggunakan teknologi informasi.
A28: 29 | F28: b. | G28: Operasionalisasi manajemen SDM sudah menggunakan teknologi informasi. | I28: a. Jika unit memiliki operasionalisasi manajemen SDM yang menggunakan teknologi informasi dan juga melakukan inovasi. b. Jika unit memiliki operasionalisasi manajemen SDM yang menggunakan teknologi informasi secara terpusat. c. Jika belum menggunakan teknologi informasi dalam operasionalisasi manajemen SDM. | J28: A/B/C | K28: A | M28: 1. Capture penggunaan teknologi/aplikasi STAR ASN. 2. Capture Inovasi terkait manajemen SDM menggunakan teknologi informasi pada satuan kerja. (jika ada) Keterangan: maksimal nilai B jika belum terdapat inovasi. | N28: A | O28: =IF(J28="Ya/Tidak",IF(N28="Ya",1,IF(N28="Tidak",0,"Blm Diisi")),IF(J28="A/B/C",IF(N28="A",1,IF(N28="B",0.5,IF(N28="C",0,"Blm Diisi"))),IF(J28="A/B/C/D",IF(N28="A",1,IF(N28="B",0.67,IF(N28="C",0.33,IF(N28="D",0,"Blm Diisi")))),IF(J28="A/B/C/D/E",IF(N28="A",1,IF(N28="B",0.75,IF(N28="C",0.5,IF(N28="D",0.25,IF(N28="E",0,"Blm Diisi"))))),IF(J28="%",IF(N28="","Blm Diisi",N28),IF(J28="Jumlah",IF(N28="","Blm Diisi",""),IF(J28="Rupiah",IF(N28="","Blm Diisi",""),IF(J28="","","-")))))))) -> 1 | R28: b. Operasionalisasi manajemen SDM sudah menggunakan teknologi informasi.
A29: 30 | F29: c. | G29: Pemberian pelayanan kepada publik sudah menggunakan teknologi informasi. | I29: a. Jika unit memberikan pelayanan kepada publik dengan menggunakan teknologi informasi terpusat/unit sendiri dan terdapat inovasi. b. Jika unit memberikan pelayanan kepada publik dengan menggunakan teknologi informasi secara terpusat. c. Jika belum memberikan pelayanan kepada publik dengan menggunakan teknologi informasi. | J29: A/B/C | K29: A | M29: 1. Capture penggunaan teknologi informasi dalam memberikan pelayanan kepada publik yang disediakan secara terpusat; 2. Capture penggunaan teknologi informasi dalam memberikan pelayanan kepada publik yang disediakan secara mandiri/ inovasi satuan kerja (jika ada). | N29: A | O29: =IF(J29="Ya/Tidak",IF(N29="Ya",1,IF(N29="Tidak",0,"Blm Diisi")),IF(J29="A/B/C",IF(N29="A",1,IF(N29="B",0.5,IF(N29="C",0,"Blm Diisi"))),IF(J29="A/B/C/D",IF(N29="A",1,IF(N29="B",0.67,IF(N29="C",0.33,IF(N29="D",0,"Blm Diisi")))),IF(J29="A/B/C/D/E",IF(N29="A",1,IF(N29="B",0.75,IF(N29="C",0.5,IF(N29="D",0.25,IF(N29="E",0,"Blm Diisi"))))),IF(J29="%",IF(N29="","Blm Diisi",N29),IF(J29="Jumlah",IF(N29="","Blm Diisi",""),IF(J29="Rupiah",IF(N29="","Blm Diisi",""),IF(J29="","","-")))))))) -> 1 | R29: c.Pemberian pelayanan kepada publik sudah menggunakan teknologi informasi.
A30: 31 | F30: d | G30: Telah dilakukan monitoring dan dan evaluasi terhadap pemanfaatan teknologi informasi dalam pengukuran kinerja unit, operasionalisasi SDM, dan pemberian layanan kepada publik. | I30: a. Jika laporan monitoring dan evaluasi terhadap pemanfaatan teknologi informasi dalam pengukuran kinerja unit, operasionalisasi SDM, dan pemberian layanan kepada publik sudah dilakukan secara berkala. b. Jika laporan monitoring dan evaluasi terhadap pemanfaatan teknologi informasi dalam pengukuran kinerja unit, operasionalisasi SDM, dan pemberian layanan kepada publik sudah dilakukan tetapi tidak secara berkala. c. Jika tidak terdapat monitoring dan evaluasi terhadap pemanfaatan teknologi informasi dalam pengukuran kinerja unit, operasionalisasi SDM, dan pemberian layanan kepada publik. | J30: A/B/C | K30: A | M30: Dokumen kegiatan monitoring dan evaluasi terhadap pemanfaatan teknologi informasi dalam pengukuran kinerja unit, operasionalisasi SDM, dan pemberian layanan kepada publik: 1. Undangan; 2. Daftar Hadir; 3. Notula dan Dokumentasi Foto; 4. Laporan Monitoring dan Evaluasi. | N30: A | O30: =IF(J30="Ya/Tidak",IF(N30="Ya",1,IF(N30="Tidak",0,"Blm Diisi")),IF(J30="A/B/C",IF(N30="A",1,IF(N30="B",0.5,IF(N30="C",0,"Blm Diisi"))),IF(J30="A/B/C/D",IF(N30="A",1,IF(N30="B",0.67,IF(N30="C",0.33,IF(N30="D",0,"Blm Diisi")))),IF(J30="A/B/C/D/E",IF(N30="A",1,IF(N30="B",0.75,IF(N30="C",0.5,IF(N30="D",0.25,IF(N30="E",0,"Blm Diisi"))))),IF(J30="%",IF(N30="","Blm Diisi",N30),IF(J30="Jumlah",IF(N30="","Blm Diisi",""),IF(J30="Rupiah",IF(N30="","Blm Diisi",""),IF(J30="","","-")))))))) -> 1 | R30: d. Telah dilakukan monitoring dan dan evaluasi terhadap pemanfaatan teknologi informasi dalam pengukuran kinerja unit, operasionalisasi SDM, dan pemberian layanan kepada publik.
A31: 32 | E31: iii. | F31: Keterbukaan Informasi Publik | H31: 0.5 | O31: =AVERAGE(O32:O33)*H31 -> 0.5 | P31: =O31/H31 -> 1
A32: 33 | F32: a. | G32: Kebijakan tentang keterbukaan informasi publik telah diterapkan. | I32: a. Jika sudah terdapat Pejabat Pengelola Informasi Publik (PPID) yang menyebarkan seluruh informasi yang dapat diakses secara mutakhir dan lengkap. b. Jika sudah terdapat PPID yang menyebarkan sebagian informasi yang dapat diakses secara mutakhir dan lengkap. c. Jika belum ada PPID dan belum melakukan penyebaran informasi publik. | J32: A/B/C | K32: A | M32: B03: 1. SK Kepala Satuan Kerja tentang Penetapan Pejabat Pengelola Informasi Publik (PPID). B03, B06, B09, B12: 2. Laporan pelaksanaan kegiatan Tim PPID dalam hal penyebarluasan informasi: a. Undangan; b. Daftar hadir; c. Notula dan Dokumentasi; d. Laporan hasil pelaksanaan keterbukaan informasi publik. | N32: A | O32: =IF(J32="Ya/Tidak",IF(N32="Ya",1,IF(N32="Tidak",0,"Blm Diisi")),IF(J32="A/B/C",IF(N32="A",1,IF(N32="B",0.5,IF(N32="C",0,"Blm Diisi"))),IF(J32="A/B/C/D",IF(N32="A",1,IF(N32="B",0.67,IF(N32="C",0.33,IF(N32="D",0,"Blm Diisi")))),IF(J32="A/B/C/D/E",IF(N32="A",1,IF(N32="B",0.75,IF(N32="C",0.5,IF(N32="D",0.25,IF(N32="E",0,"Blm Diisi"))))),IF(J32="%",IF(N32="","Blm Diisi",N32),IF(J32="Jumlah",IF(N32="","Blm Diisi",""),IF(J32="Rupiah",IF(N32="","Blm Diisi",""),IF(J32="","","-")))))))) -> 1 | R32: a. Kebijakan tentang keterbukaan informasi publik telah diterapkan
A33: 34 | F33: b. | G33: Telah dilakukan monitoring dan evaluasi pelaksanaan kebijakan keterbukaan informasi publik. | I33: a. Jika dilakukan monitoring dan evaluasi pelaksanaan kebijakan keterbukaan informasi publik dan telah ditindaklanjuti. b. Jika monitoring dan evaluasi pelaksanaan kebijakan keterbukaan informasi publik telah dilakukan tetapi belum ditindaklanjuti. c. Jika monitoring dan evaluasi pelaksanaan kebijakan keterbukaan informasi publik belum dilakukan. | J33: A/B/C | K33: A | M33: 1. Laporan hasil monitoring dan evaluasi pelaksanaan kebijakan keterbukaan informasi publik oleh tim PPID. 2. Laporan tindak lanjut monitoring dan evaluasi. | N33: A | O33: =IF(J33="Ya/Tidak",IF(N33="Ya",1,IF(N33="Tidak",0,"Blm Diisi")),IF(J33="A/B/C",IF(N33="A",1,IF(N33="B",0.5,IF(N33="C",0,"Blm Diisi"))),IF(J33="A/B/C/D",IF(N33="A",1,IF(N33="B",0.67,IF(N33="C",0.33,IF(N33="D",0,"Blm Diisi")))),IF(J33="A/B/C/D/E",IF(N33="A",1,IF(N33="B",0.75,IF(N33="C",0.5,IF(N33="D",0.25,IF(N33="E",0,"Blm Diisi"))))),IF(J33="%",IF(N33="","Blm Diisi",N33),IF(J33="Jumlah",IF(N33="","Blm Diisi",""),IF(J33="Rupiah",IF(N33="","Blm Diisi",""),IF(J33="","","-")))))))) -> 1 | R33: b. Telah dilakukan monitoring dan evaluasi pelaksanaan kebijakan keterbukaan informasi publik.
A34: 35 | D34: 3. | E34: PENATAAN SISTEM MANAJEMEN SDM APARATUR | H34: 5 | O34: =SUM(O35,O39,O43,O50,O55,O57) -> 5 | P34: =O34/H34 -> 1
A35: 36 | E35: i. | F35: Perencanaan Kebutuhan Pegawai sesuai dengan Kebutuhan Organisasi | H35: 0.25 | O35: =AVERAGE(O36:O38)*H35 -> 0.25 | P35: =O35/H35 -> 1
A36: 37 | F36: a. | G36: Kebutuhan pegawai yang disusun oleh unit kerja mengacu kepada peta jabatan dan hasil analisis beban kerja untuk masing-masing jabatan. | I36: Ya, jika kebutuhan pegawai yang disusun oleh unit kerja mengacu kepada peta jabatan dan hasil analisis beban kerja untuk masing-masing jabatan. | J36: Ya/Tidak | K36: Ya | M36: 1. Peta Jabatan mengacu kepada format Lampiran VI Perka BKN Nomor 9 Tahun 2022 tentang Tata Cara Pelaksanaan Penyusunan Kebutuhan ASN yang ditandatangani oleh kepala satuan kerja. 2. Analisis Jabatan mengacu kepada format dalam Lampiran I s.d. V Peraturan BKN Nomor 9 Tahun 2022 tentang Tata Cara Pelaksanaan Penyusunan Kebutuhan ASN. 3. Dokumen Kebutuhan Pegawai mengacu kepada format dalam Lampiran VII Perka BKN Nomor 9 Tahun 2022 tentang Tata Cara Pelaksanaan Penyusunan Kebutuhan ASN. 4. Surat usulan kebutuhan pegawai dari Unit Kerja yang ditujukan kepada Sekretariat Jenderal melalui Kanwil. 5. Dokumen Rapat kebutuhan pegawai berupa Undangan, Daftar Hadir, Notula dan Dokumentasi Foto sesuai dengan ketentuan yang berlaku mengenai tata naskah dinas di lingkungan Kementerian Imigrasi dan Pemasyarakatan . Keterangan: Jika terdapat perubahan diupdate pada triwulan berikutnya. | N36: Ya | O36: =IF(J36="Ya/Tidak",IF(N36="Ya",1,IF(N36="Tidak",0,"Blm Diisi")),IF(J36="A/B/C",IF(N36="A",1,IF(N36="B",0.5,IF(N36="C",0,"Blm Diisi"))),IF(J36="A/B/C/D",IF(N36="A",1,IF(N36="B",0.67,IF(N36="C",0.33,IF(N36="D",0,"Blm Diisi")))),IF(J36="A/B/C/D/E",IF(N36="A",1,IF(N36="B",0.75,IF(N36="C",0.5,IF(N36="D",0.25,IF(N36="E",0,"Blm Diisi"))))),IF(J36="%",IF(N36="","Blm Diisi",N36),IF(J36="Jumlah",IF(N36="","Blm Diisi",""),IF(J36="Rupiah",IF(N36="","Blm Diisi",""),IF(J36="","","-")))))))) -> 1 | R36: a. Kebutuhan pegawai yang disusun oleh unit kerja mengacu kepada peta jabatan dan hasil analisis beban kerja untuk masing-masing jabatan.
A37: 38 | F37: b. | G37: Penempatan pegawai hasil rekrutmen murni mengacu kepada kebutuhan pegawai yang telah disusun per jabatan. | I37: a. Jika semua penempatan pegawai hasil rekrutmen murni mengacu kepada kebutuhan pegawai yang telah disusun per jabatan. b. Jika sebagian besar penempatan pegawai hasil rekrutmen murni mengacu kepada kebutuhan pegawai yang telah disusun per jabatan. c. Jika sebagian kecil penempatan pegawai hasil rekrutmen murni mengacu kepada kebutuhan pegawai yang telah disusun per jabatan. d. Jika penempatan pegawai hasil rekrutmen murni tidak mengacu kepada kebutuhan pegawai yang telah disusun per jabatan. | J37: A/B/C/D | K37: A | M37: 1. SK CPNS hasil dari Penerimaan CPNS yang terakhir/terbaru. 2. Surat pengantar penempatan CPNS dari Kanwil ke Unit Kerja. 3. Surat Perintah Melaksanakan Tugas (SPMT) dari Kepala Satuan Kerja. 4. Surat Keputusan MenPANRB tentang Penetapan Kebutuhan PNS di Lingkungan Kementerian Imigrasi dan Pemasyarakatan Tahun Anggaran terakhir. Dokumen ini didapatkan dari Biro SDMA, Organisasi dan Ketatalaksanaan. | N37: A | O37: =IF(J37="Ya/Tidak",IF(N37="Ya",1,IF(N37="Tidak",0,"Blm Diisi")),IF(J37="A/B/C",IF(N37="A",1,IF(N37="B",0.5,IF(N37="C",0,"Blm Diisi"))),IF(J37="A/B/C/D",IF(N37="A",1,IF(N37="B",0.67,IF(N37="C",0.33,IF(N37="D",0,"Blm Diisi")))),IF(J37="A/B/C/D/E",IF(N37="A",1,IF(N37="B",0.75,IF(N37="C",0.5,IF(N37="D",0.25,IF(N37="E",0,"Blm Diisi"))))),IF(J37="%",IF(N37="","Blm Diisi",N37),IF(J37="Jumlah",IF(N37="","Blm Diisi",""),IF(J37="Rupiah",IF(N37="","Blm Diisi",""),IF(J37="","","-")))))))) -> 1 | R37: b. Penempatan pegawai hasil rekrutmen murni mengacu kepada kebutuhan pegawai yang telah disusun per jabatan.
A38: 39 | F38: c. | G38: Telah dilakukan monitoring dan dan evaluasi terhadap penempatan pegawai rekrutmen untuk memenuhi kebutuhan jabatan dalam organisasi telah memberikan perbaikan terhadap kinerja unit kerja. | I38: Ya, jika sudah dilakukan monitoring dan evaluasi terhadap penempatan pegawai hasil rekrutmen untuk memenuhi kebutuhan jabatan dalam organisasi telah memberikan perbaikan terhadap kinerja unit kerja. | J38: Ya/Tidak | K38: Ya | M38: Dokumen kegiatan monitoring dan evaluasi tentang penempatan pegawai terhadap kinerja unit: 1. Undangan; 2. Daftar hadir; 3. Notula dan dokumentasi foto; 4. Laporan hasil monitoring dan evaluasi tentang penempatan pegawai terhadap kinerja unit. | N38: Ya | O38: =IF(J38="Ya/Tidak",IF(N38="Ya",1,IF(N38="Tidak",0,"Blm Diisi")),IF(J38="A/B/C",IF(N38="A",1,IF(N38="B",0.5,IF(N38="C",0,"Blm Diisi"))),IF(J38="A/B/C/D",IF(N38="A",1,IF(N38="B",0.67,IF(N38="C",0.33,IF(N38="D",0,"Blm Diisi")))),IF(J38="A/B/C/D/E",IF(N38="A",1,IF(N38="B",0.75,IF(N38="C",0.5,IF(N38="D",0.25,IF(N38="E",0,"Blm Diisi"))))),IF(J38="%",IF(N38="","Blm Diisi",N38),IF(J38="Jumlah",IF(N38="","Blm Diisi",""),IF(J38="Rupiah",IF(N38="","Blm Diisi",""),IF(J38="","","-")))))))) -> 1 | R38: c. Telah dilakukan monitoring dan dan evaluasi terhadap penempatan pegawai rekrutmen untuk memenuhi kebutuhan jabatan dalam organisasi telah memberikan perbaikan terhadap kinerja unit kerja.
A39: 40 | E39: ii. | F39: Pola Mutasi Internal | H39: 0.5 | O39: =AVERAGE(O40:O42)*H39 -> 0.5 | P39: =O39/H39 -> 1
A40: 41 | F40: a. | G40: Dalam melakukan pengembangan karier pegawai, telah dilakukan mutasi pegawai antar jabatan. | I40: Ya, jika dilakukan mutasi pegawai antar jabatan sebagai wujud dari pengembangan karier pegawai. | J40: Ya/Tidak | K40: Ya | M40: 1. Dokumen rapat pembahasan mutasi/rotasi antar jabatan berupa undangan, daftar hadir, dokumentasi dan notula yang memuat upaya pengembangan karir sebagai dasar pertimbangan mutasi/rotasi. Format dokumen disesuaikan dengan Keputusan Menteri Imigrasi dan Pemasyarakatan Nomor M.IP-10.HK.03. 02 Tahun 2025. 2. SK mutasi/rotasi atau surat usulan mutasi/rotasi dari UPT, Kanwil dan/atau Unit Utama. 3. Daftar Riwayat Pekerjaan/ Hidup (DRP/DRH). Keterangan: Jika terdapat perubahan diupdate pada triwulan berikutnya. | N40: Ya | O40: =IF(J40="Ya/Tidak",IF(N40="Ya",1,IF(N40="Tidak",0,"Blm Diisi")),IF(J40="A/B/C",IF(N40="A",1,IF(N40="B",0.5,IF(N40="C",0,"Blm Diisi"))),IF(J40="A/B/C/D",IF(N40="A",1,IF(N40="B",0.67,IF(N40="C",0.33,IF(N40="D",0,"Blm Diisi")))),IF(J40="A/B/C/D/E",IF(N40="A",1,IF(N40="B",0.75,IF(N40="C",0.5,IF(N40="D",0.25,IF(N40="E",0,"Blm Diisi"))))),IF(J40="%",IF(N40="","Blm Diisi",N40),IF(J40="Jumlah",IF(N40="","Blm Diisi",""),IF(J40="Rupiah",IF(N40="","Blm Diisi",""),IF(J40="","","-")))))))) -> 1 | R40: a. Dalam melakukan pengembangan karier pegawai, telah dilakukan mutasi pegawai antar jabatan.
...

Sheet Jawaban dari Kanwil
A1: 1 | B1: Penilaian | H1: Bobot | I1: Kriteria Nilai | J1: Pilihan Jawaban | K1: Jawaban Unit | L1: Catatan/Keterangan/Penjelasan Unit | M1: Bukti Dukung Unit | N1: Jawaban dari Kanwil | O1: Nilai dari Kanwil | P1: % | Q1: Catatan/Keterangan/Penjelasan Evaluasi dari Kanwil | R1: Link Google Drive Data Dukung B03 | S1: Link Google Drive Data Dukung B06 | T1: Link Google Drive Data Dukung B09 | U1: Link Google Drive Data Dukung B12 | V1: Link Google Drive Data Dukung B12 Tahun Sebelumnya
A2: 3 | B2: A. | C2: PENGUNGKIT | H2: 60 | O2: =O195 -> 60 | P2: =O2/H2 -> 1
A3: 4 | C3: I. | D3: PEMENUHAN | H3: 30 | O3: =SUM(O4,O21,O34,O59,O73,O97) -> 30 | P3: =O3/H3 -> 1
A4: 5 | D4: 1. | E4: MANAJEMEN PERUBAHAN | H4: 4 | O4: =SUM(O5,O8,O12,O16) -> 4 | P4: =O4/H4 -> 1
A5: 6 | E5: i. | F5: Penyusunan Tim Kerja | H5: 0.5 | O5: =AVERAGE(O6:O7)*H5 -> 0.5 | P5: =O5/H5 -> 1
A6: 7 | F6: a. | G6: Unit kerja telah membentuk tim untuk melakukan pembangunan Zona Integritas. | I6: Ya, jika Tim telah dibentuk di dalam unit kerja. | J6: Ya/Tidak | K6: =Jawaban!K6 -> Ya | L6: =Jawaban!L6 -> 0 | M6: 1. SK Tim Kerja Pembangunan ZI Menuju WBK/WBBM; 2. SK Perubahan atas SK Tim Kerja Pembangunan ZI Menuju WBK/WBBM (jika ada); 3. SK Perubahan (Kedua, Ketiga, dst) atas SK Tim Kerja Pembangunan ZI Menuju WBK/WBBM (jika ada). Keterangan: Apabila ada penggantian Kepala Satuan Kerja ditambahkan dengan SK Tim Baru. | N6: Ya | O6: =IF(J6="Ya/Tidak",IF(N6="Ya",1,IF(N6="Tidak",0,"Blm Diisi")),IF(J6="A/B/C",IF(N6="A",1,IF(N6="B",0.5,IF(N6="C",0,"Blm Diisi"))),IF(J6="A/B/C/D",IF(N6="A",1,IF(N6="B",0.67,IF(N6="C",0.33,IF(N6="D",0,"Blm Diisi")))),IF(J6="A/B/C/D/E",IF(N6="A",1,IF(N6="B",0.75,IF(N6="C",0.5,IF(N6="D",0.25,IF(N6="E",0,"Blm Diisi"))))),IF(J6="%",IF(N6="","Blm Diisi",N6),IF(J6="Jumlah",IF(N6="","Blm Diisi",""),IF(J6="Rupiah",IF(N6="","Blm Diisi",""),IF(J6="","","-")))))))) -> 1 | Q6: Tercapai, Dakung yang diminta sudah lengkap | R6: =Jawaban!R6 -> a. Unit kerja telah membentuk tim untuk melakukan pembangunan Zona Integritas. | S6: =Jawaban!S6 -> 0 | T6: =Jawaban!T6 -> 0 | U6: =Jawaban!U6 -> 0 | V6: =Jawaban!V6 -> 0
A7: 8 | F7: b. | G7: Penentuan anggota Tim dipilih melalui prosedur/mekanisme yang jelas. | I7: a. Jika dengan prosedur/mekanisme yang jelas dan mewakili seluruh unsur dalam unit kerja. b. Jika sebagian menggunakan prosedur yang mewakili sebagian besar unsur dalam unit kerja. c. Jika tidak di seleksi. | J7: A/B/C | K7: =Jawaban!K7 -> A | L7: =Jawaban!L7 -> 0 | M7: Dokumen Kegiatan Rapat Tim Kerja: 1. undangan rapat; 2. daftar hadir; 3. notula dan dokumentasi foto; 4. SK Tim Seleksi; 5. berita acara; 6. laporan pelaksanaan seleksi anggota tim kerja; 7. Daftar Riwayat Hidup dan Daftar Riwayat Pekerjaan (diunduh melalui aplikasi STAR ASN KemenIMIPAS). | N7: A | O7: =IF(J7="Ya/Tidak",IF(N7="Ya",1,IF(N7="Tidak",0,"Blm Diisi")),IF(J7="A/B/C",IF(N7="A",1,IF(N7="B",0.5,IF(N7="C",0,"Blm Diisi"))),IF(J7="A/B/C/D",IF(N7="A",1,IF(N7="B",0.67,IF(N7="C",0.33,IF(N7="D",0,"Blm Diisi")))),IF(J7="A/B/C/D/E",IF(N7="A",1,IF(N7="B",0.75,IF(N7="C",0.5,IF(N7="D",0.25,IF(N7="E",0,"Blm Diisi"))))),IF(J7="%",IF(N7="","Blm Diisi",N7),IF(J7="Jumlah",IF(N7="","Blm Diisi",""),IF(J7="Rupiah",IF(N7="","Blm Diisi",""),IF(J7="","","-")))))))) -> 1 | Q7: Tercapai, Dakung yang diminta sudah lengkap | R7: =Jawaban!R7 -> b. Penentuan anggota Tim dipilih melalui prosedur/mekanisme yang jelas. | S7: =Jawaban!S7 -> 0 | T7: =Jawaban!T7 -> 0 | U7: =Jawaban!U7 -> 0 | V7: =Jawaban!V7 -> 0
A8: 9 | E8: ii. | F8: Rencana Pembangunan Zona Integritas | H8: 1 | K8: =Jawaban!K8 -> 0 | L8: =Jawaban!L8 -> 0 | O8: =AVERAGE(O9:O11)*H8 -> 1 | P8: =O8/H8 -> 1 | R8: =Jawaban!R8 -> 0 | S8: =Jawaban!S8 -> 0 | T8: =Jawaban!T8 -> 0 | U8: =Jawaban!U8 -> 0 | V8: =Jawaban!V8 -> 0
A9: 10 | F9: a. | G9: Terdapat dokumen rencana kerja pembangunan Zona Integritas menuju WBK/WBBM. | I9: Ya, jika memiliki rencana kerja pembangunan Zona Integritas. | J9: Ya/Tidak | K9: =Jawaban!K9 -> Ya | L9: =Jawaban!L9 -> 0 | M9: Dokumen kegiatan Rapat Penetapan Rencana Kerja dan Target Prioritas: 1. Undangan rapat; 2. daftar hadir; 3. notula dan dokumentasi foto; 4. laporan kegiatan rapat penetapan Rencana Kerja; 5. SK tentang Rencana Kerja dan Target Prioritas Pembangunan ZI menuju WBK/WBBM satuan kerja yang ditandatangani oleh Kepala Satuan Kerja. | N9: Ya | O9: =IF(J9="Ya/Tidak",IF(N9="Ya",1,IF(N9="Tidak",0,"Blm Diisi")),IF(J9="A/B/C",IF(N9="A",1,IF(N9="B",0.5,IF(N9="C",0,"Blm Diisi"))),IF(J9="A/B/C/D",IF(N9="A",1,IF(N9="B",0.67,IF(N9="C",0.33,IF(N9="D",0,"Blm Diisi")))),IF(J9="A/B/C/D/E",IF(N9="A",1,IF(N9="B",0.75,IF(N9="C",0.5,IF(N9="D",0.25,IF(N9="E",0,"Blm Diisi"))))),IF(J9="%",IF(N9="","Blm Diisi",N9),IF(J9="Jumlah",IF(N9="","Blm Diisi",""),IF(J9="Rupiah",IF(N9="","Blm Diisi",""),IF(J9="","","-")))))))) -> 1 | Q9: Tercapai, Dakung yang diminta sudah lengkap | R9: =Jawaban!R9 -> a. Terdapat dokumen rencana kerja pembangunan Zona Integritas menuju WBK/WBBM. | S9: =Jawaban!S9 -> 0 | T9: =Jawaban!T9 -> 0 | U9: =Jawaban!U9 -> 0 | V9: =Jawaban!V9 -> 0
A10: 11 | F10: b. | G10: Dalam dokumen pembangunan terdapat target-target prioritas yang relevan dengan tujuan pembangunan WBK/WBBM. | I10: a. Jika semua target-target prioritas relevan dengan tujuan pembangunan WBK/WBBM. b. Jika sebagian target-target prioritas relevan dengan tujuan pembangunan WBK/WBBM. c. Jika tidak ada target-target prioritas yang relevan dengan tujuan pembangunan WBK/WBBM. | J10: A/B/C | K10: =Jawaban!K10 -> A | L10: =Jawaban!L10 -> 0 | M10: Dokumen kegiatan rapat penetapan Rencana Kerja dan Target Prioritas: 1. undangan rapat; 2. daftar hadir; 3. notula dan dokumentasi foto; 4. laporan kegiatan rapat penetapan Rencana Kerja; 5. SK tentang Rencana Kerja dan Target Prioritas Pembangunan ZI menuju WBK/WBBM satuan kerja yang ditandatangani oleh Kepala Satuan Kerja. | N10: A | O10: =IF(J10="Ya/Tidak",IF(N10="Ya",1,IF(N10="Tidak",0,"Blm Diisi")),IF(J10="A/B/C",IF(N10="A",1,IF(N10="B",0.5,IF(N10="C",0,"Blm Diisi"))),IF(J10="A/B/C/D",IF(N10="A",1,IF(N10="B",0.67,IF(N10="C",0.33,IF(N10="D",0,"Blm Diisi")))),IF(J10="A/B/C/D/E",IF(N10="A",1,IF(N10="B",0.75,IF(N10="C",0.5,IF(N10="D",0.25,IF(N10="E",0,"Blm Diisi"))))),IF(J10="%",IF(N10="","Blm Diisi",N10),IF(J10="Jumlah",IF(N10="","Blm Diisi",""),IF(J10="Rupiah",IF(N10="","Blm Diisi",""),IF(J10="","","-")))))))) -> 1 | Q10: Tercapai, Dakung yang diminta sudah lengkap | R10: =Jawaban!R10 -> b. Dalam dokumen pembangunan terdapat target-target prioritas yang relevan dengan tujuan pembangunan WBK/WBBM. | S10: =Jawaban!S10 -> 0 | T10: =Jawaban!T10 -> 0 | U10: =Jawaban!U10 -> 0 | V10: =Jawaban!V10 -> 0
A11: 12 | F11: c. | G11: Terdapat mekanisme atau media untuk mensosialisasikan pembangunan WBK/WBBM. | I11: a. Jika telah dilakukan pengelolaan media/ aktivitas interaktif yang efektif untuk menginformasikan pembangunan ZI kepada internal dan stakeholder secara berkala. b. Jika pengelolaan media/aktivitas interaktif dilakukan secara terbatas dan tidak secara berkala. c. Jika pengelolaan media/aktivitas interaktif belum dilakukan. | J11: A/B/C | K11: =Jawaban!K11 -> A | L11: =Jawaban!L11 -> 0 | M11: B03: 1. Dokumen laporan pelaksanaan kegiatan Pencanangan Zona Integritas, yaitu: a. Kegiatan Ekternal Pencanangan Zona Integritas melampirkan Foto, Laporan Kegiatan dan Press release. b. Kegiatan Internal 1) Dokumen Perjanjian Kinerja; 2) Dokumen Penandatanganan Pakta Integritas antara Kepala Satuan Kerja dengan jajaran struktural dibawahnya; 3) Dokumen Pakta Integritas antara jajaran Struktural dalam satuan kerja dengan pegawai. B03, B06, B09, B12: 2. Dokumen kegiatan sosialisasi Kepala satuan kerja/ internalisasi/pembinaan/pendampingan terkait Pembangunan ZI menuju WBK/WBBM: a. undangan; b. daftar hadir; c. notula dan dokumentasi foto; d. laporan kegiatan. 3. Dokumen sosialisasi kepada masyarakat: (minimal 3 dari data dukung di bawah) a. Capture Banner/spanduk/himbauan/brosur; b. Capture Website; c. Capture Media Sosial; d. Capture Media elektronik; e. Capture Media cetak; f. Capture Media TV; g. Laporan kegiatan sosialisasi kepada masyarakat. | N11: A | O11: =IF(J11="Ya/Tidak",IF(N11="Ya",1,IF(N11="Tidak",0,"Blm Diisi")),IF(J11="A/B/C",IF(N11="A",1,IF(N11="B",0.5,IF(N11="C",0,"Blm Diisi"))),IF(J11="A/B/C/D",IF(N11="A",1,IF(N11="B",0.67,IF(N11="C",0.33,IF(N11="D",0,"Blm Diisi")))),IF(J11="A/B/C/D/E",IF(N11="A",1,IF(N11="B",0.75,IF(N11="C",0.5,IF(N11="D",0.25,IF(N11="E",0,"Blm Diisi"))))),IF(J11="%",IF(N11="","Blm Diisi",N11),IF(J11="Jumlah",IF(N11="","Blm Diisi",""),IF(J11="Rupiah",IF(N11="","Blm Diisi",""),IF(J11="","","-")))))))) -> 1 | Q11: Tercapai, Dakung yang diminta sudah lengkap | R11: =Jawaban!R11 -> c. Terdapat mekanisme atau media untuk mensosialisasikan pembangunan WBK/WBBM. | S11: =Jawaban!S11 -> 0 | T11: =Jawaban!T11 -> 0 | U11: =Jawaban!U11 -> 0 | V11: =Jawaban!V11 -> 0
A12: 13 | E12: iii. | F12: Pemantauan dan Evaluasi Pembangunan WBK/WBBM | H12: 1 | K12: =Jawaban!K12 -> 0 | L12: =Jawaban!L12 -> 0 | O12: =AVERAGE(O13:O15)*H12 -> 1 | P12: =O12/H12 -> 1 | R12: =Jawaban!R12 -> 0 | S12: =Jawaban!S12 -> 0 | T12: =Jawaban!T12 -> 0 | U12: =Jawaban!U12 -> 0 | V12: =Jawaban!V12 -> 0
A13: 14 | F13: a. | G13: Seluruh kegiatan pembangunan sudah dilaksanakan sesuai dengan rencana. | I13: a. Jika semua kegiatan pembangunan telah dilaksanakan sesuai dengan rencana. b. Jika sebagian besar kegiatan pembangunan telah dilaksanakan sesuai dengan rencana. c. Jika sebagian kecil kegiatan pembangunan telah dilaksanakan sesuai dengan rencana. d. Jika belum ada kegiatan pembangunan yang dilakukan sesuai dengan rencana. | J13: A/B/C/D | K13: =Jawaban!K13 -> A | L13: =Jawaban!L13 -> 0 | M13: Dokumen kegiatan rapat pelaksanaan Rencana Aksi dan Target Prioritas oleh Tim Kerja: 1. undangan rapat; 2. daftar hadir; 3. notula dan dokumentasi foto; 4. laporan kegiatan kegiatan pembangunan ZI berdasarkan Rencana Aksi dan Target Prioritas. | N13: A | O13: =IF(J13="Ya/Tidak",IF(N13="Ya",1,IF(N13="Tidak",0,"Blm Diisi")),IF(J13="A/B/C",IF(N13="A",1,IF(N13="B",0.5,IF(N13="C",0,"Blm Diisi"))),IF(J13="A/B/C/D",IF(N13="A",1,IF(N13="B",0.67,IF(N13="C",0.33,IF(N13="D",0,"Blm Diisi")))),IF(J13="A/B/C/D/E",IF(N13="A",1,IF(N13="B",0.75,IF(N13="C",0.5,IF(N13="D",0.25,IF(N13="E",0,"Blm Diisi"))))),IF(J13="%",IF(N13="","Blm Diisi",N13),IF(J13="Jumlah",IF(N13="","Blm Diisi",""),IF(J13="Rupiah",IF(N13="","Blm Diisi",""),IF(J13="","","-")))))))) -> 1 | Q13: Tercapai, Dakung yang diminta sudah lengkap | R13: =Jawaban!R13 -> a. Seluruh kegiatan pembangunan sudah dilaksanakan sesuai dengan rencana. | S13: =Jawaban!S13 -> 0 | T13: =Jawaban!T13 -> 0 | U13: =Jawaban!U13 -> 0 | V13: =Jawaban!V13 -> 0
A14: 15 | F14: b. | G14: Terdapat monitoring dan evaluasi terhadap pembangunan Zona Integritas. | I14: a. Jika monitoring dan evaluasi melibatkan pimpinan dan dilakukan secara berkala. b. Jika monitoring dan evaluasi melibatkan pimpinan tetapi tidak secara berkala. c. Jika monitoring dan evaluasi tidak melibatkan pimpinan dan tidak secara berkala. d. Jika tidak terdapat monitoring dan evaluasi terhadap pembangunan zona integritas. | J14: A/B/C/D | K14: =Jawaban!K14 -> A | L14: =Jawaban!L14 -> 0 | M14: Dokumen kegiatan penyusunan laporan hasil monitoring dan evaluasi: 1. undangan rapat; 2. daftar hadir; 3. notula dan dokumentasi foto; 4. laporan hasil monitoring dan evaluasi triwulan. | N14: A | O14: =IF(J14="Ya/Tidak",IF(N14="Ya",1,IF(N14="Tidak",0,"Blm Diisi")),IF(J14="A/B/C",IF(N14="A",1,IF(N14="B",0.5,IF(N14="C",0,"Blm Diisi"))),IF(J14="A/B/C/D",IF(N14="A",1,IF(N14="B",0.67,IF(N14="C",0.33,IF(N14="D",0,"Blm Diisi")))),IF(J14="A/B/C/D/E",IF(N14="A",1,IF(N14="B",0.75,IF(N14="C",0.5,IF(N14="D",0.25,IF(N14="E",0,"Blm Diisi"))))),IF(J14="%",IF(N14="","Blm Diisi",N14),IF(J14="Jumlah",IF(N14="","Blm Diisi",""),IF(J14="Rupiah",IF(N14="","Blm Diisi",""),IF(J14="","","-")))))))) -> 1 | Q14: Tercapai, Dakung yang diminta sudah lengkap | R14: =Jawaban!R14 -> b. Terdapat monitoring dan evaluasi terhadap pembangunan Zona Integritas. | S14: =Jawaban!S14 -> 0 | T14: =Jawaban!T14 -> 0 | U14: =Jawaban!U14 -> 0 | V14: =Jawaban!V14 -> 0
A15: 16 | F15: c. | G15: Hasil Monitoring dan Evaluasi telah ditindaklanjuti. | I15: a. Jika semua catatan/rekomendasi hasil monitoring dan evaluasi tim internal atas persiapan dan pelaksanaan kegiatan Unit WBK/WBBM telah ditindaklanjuti. b. Jika sebagian besar catatan/rekomendasi hasil monitoring danevaluasi tim internal atas persiapan dan pelaksanaan kegiatan Unit WBK/WBBM telah ditindaklanjuti. c. Jika sebagian kecil catatan/rekomendasi hasil monitoring dan evaluasi tim internal atas persiapan dan pelaksanaan kegiatan Unit WBK/WBBM telah ditindaklanjuti. d. Jika catatan/rekomendasi hasil monitoring dan evaluasi tim internal atas persiapan dan pelaksanaan kegiatan Unit WBK/WBBM belum ditindaklanjuti. | J15: A/B/C/D | K15: =Jawaban!K15 -> A | L15: =Jawaban!L15 -> 0 | M15: Dokumen kegiatan penyusunan laporan tindak lanjut hasil monitoring dan evaluasi: 1. undangan rapat; 2. daftar hadir; 3. notula dan dokumentasi foto; 4. laporan tindak lanjut hasil monitoring dan evaluasi. | N15: A | O15: =IF(J15="Ya/Tidak",IF(N15="Ya",1,IF(N15="Tidak",0,"Blm Diisi")),IF(J15="A/B/C",IF(N15="A",1,IF(N15="B",0.5,IF(N15="C",0,"Blm Diisi"))),IF(J15="A/B/C/D",IF(N15="A",1,IF(N15="B",0.67,IF(N15="C",0.33,IF(N15="D",0,"Blm Diisi")))),IF(J15="A/B/C/D/E",IF(N15="A",1,IF(N15="B",0.75,IF(N15="C",0.5,IF(N15="D",0.25,IF(N15="E",0,"Blm Diisi"))))),IF(J15="%",IF(N15="","Blm Diisi",N15),IF(J15="Jumlah",IF(N15="","Blm Diisi",""),IF(J15="Rupiah",IF(N15="","Blm Diisi",""),IF(J15="","","-")))))))) -> 1 | Q15: Tercapai, Dakung yang diminta sudah lengkap | R15: =Jawaban!R15 -> c. Hasil Monitoring dan Evaluasi telah ditindaklanjuti. | S15: =Jawaban!S15 -> 0 | T15: =Jawaban!T15 -> 0 | U15: =Jawaban!U15 -> 0 | V15: =Jawaban!V15 -> 0
A16: 17 | E16: iv. | F16: Perubahan pola pikir dan budaya kerja | H16: 1.5 | K16: =Jawaban!K16 -> 0 | L16: =Jawaban!L16 -> 0 | O16: =AVERAGE(O17:O20)*H16 -> 1.5 | P16: =O16/H16 -> 1 | R16: =Jawaban!R16 -> 0 | S16: =Jawaban!S16 -> 0 | T16: =Jawaban!T16 -> 0 | U16: =Jawaban!U16 -> 0 | V16: =Jawaban!V16 -> 0
A17: 18 | F17: a. | G17: Pimpinan berperan sebagai role model dalam pelaksanaan Pembangunan WBK/WBBM. | I17: ya, jika pimpinan menjadi contoh pelaksanaan nilai-nilai organisasi. | J17: Ya/Tidak | K17: =Jawaban!K17 -> Ya | L17: =Jawaban!L17 -> 0 | M17: 1. Arahan kepala satuan kerja terkait pembangunan ZI dan nilai dasar/core value: a. undangan; b. daftar hadir; c. notula; d. laporan. 2. Absensi pimpinan Satker dan pejabat struktural (Misal sampling: Bulan Januari, Februari, dan Maret) (data dukung diperbaharui tiap triwulan). 3. Dokumentasi pimpinan/pejabat struktural menjadi Pembina apel dan pembina upacara. (data dukung diperbaharui tiap triwulan). 4. Dokumen Jurnal Harian Pimpinan dan Pejabat Struktural (Sampling: Bulan Januari, Februari, dan Maret) (data dukung diperbaharui tiap triwulan): a. Untuk satuan kerja Eselon I, daftar hadir dan jurnal harian yang dibutuhkan sampai kepada Jabatan Struktural Eselon I, II, dan III; b. Untuk satuan kerja Eselon II, daftar hadir dan jurnal harian yang dibutuhkan sampai kepada Jabatan Struktural Eselon II dan III; c. Untuk satuan kerja Eselon III, daftar hadir dan jurnal harian yang dibutuhkan sampai kepada Jabatan Struktural Eselon III dan IV. | N17: Ya | O17: =IF(J17="Ya/Tidak",IF(N17="Ya",1,IF(N17="Tidak",0,"Blm Diisi")),IF(J17="A/B/C",IF(N17="A",1,IF(N17="B",0.5,IF(N17="C",0,"Blm Diisi"))),IF(J17="A/B/C/D",IF(N17="A",1,IF(N17="B",0.67,IF(N17="C",0.33,IF(N17="D",0,"Blm Diisi")))),IF(J17="A/B/C/D/E",IF(N17="A",1,IF(N17="B",0.75,IF(N17="C",0.5,IF(N17="D",0.25,IF(N17="E",0,"Blm Diisi"))))),IF(J17="%",IF(N17="","Blm Diisi",N17),IF(J17="Jumlah",IF(N17="","Blm Diisi",""),IF(J17="Rupiah",IF(N17="","Blm Diisi",""),IF(J17="","","-")))))))) -> 1 | Q17: Tercapai, Dakung yang diminta sudah lengkap | R17: =Jawaban!R17 -> a. Pimpinan berperan sebagai role model dalam pelaksanaan Pembangunan WBK/WBBM. | S17: =Jawaban!S17 -> 0 | T17: =Jawaban!T17 -> 0 | U17: =Jawaban!U17 -> 0 | V17: =Jawaban!V17 -> 0
A18: 19 | F18: b. | G18: Sudah ditetapkan agen perubahan. | I18: a. Jika agen perubahan telah ditetapkan dan berkontribusi terhadap perubahan pada unit kerjanya. b. Jika agen perubahan telah ditetapkan namun belum berkontribusi terhadap perubahan pada unit kerjanya. c. Jika belum terdapat agen perubahan. | J18: A/B/C | K18: =Jawaban!K18 -> A | L18: =Jawaban!L18 -> 0 | M18: Dokumen pelaksanaan kegiatan penetapan Agen Perubahan: 1. undangan; 2. daftar hadir; 3. notula dan dokumentasi foto; 4. Riwayat Hidup dan rekam jejak agen perubahan; 5. SK Agen Perubahan yang ditetapkan oleh Kepala Satuan Kerja. Keterangan : Masing-masing Agen Perubahan yang ditunjuk harus memiliki prestasi/kontribusi dalam pembangunan ZI dan satu agen perubahan minimal memiliki satu produk perubahan, yang terintegrasi dengan Sistem Manajemen pada satuan kerja (tidak termasuk jingle, maskot, jargon). | N18: A | O18: =IF(J18="Ya/Tidak",IF(N18="Ya",1,IF(N18="Tidak",0,"Blm Diisi")),IF(J18="A/B/C",IF(N18="A",1,IF(N18="B",0.5,IF(N18="C",0,"Blm Diisi"))),IF(J18="A/B/C/D",IF(N18="A",1,IF(N18="B",0.67,IF(N18="C",0.33,IF(N18="D",0,"Blm Diisi")))),IF(J18="A/B/C/D/E",IF(N18="A",1,IF(N18="B",0.75,IF(N18="C",0.5,IF(N18="D",0.25,IF(N18="E",0,"Blm Diisi"))))),IF(J18="%",IF(N18="","Blm Diisi",N18),IF(J18="Jumlah",IF(N18="","Blm Diisi",""),IF(J18="Rupiah",IF(N18="","Blm Diisi",""),IF(J18="","","-")))))))) -> 1 | Q18: Tercapai, Dakung yang diminta sudah lengkap | R18: =Jawaban!R18 -> b. Sudah ditetapkan agen perubahan. | S18: =Jawaban!S18 -> 0 | T18: =Jawaban!T18 -> 0 | U18: =Jawaban!U18 -> 0 | V18: =Jawaban!V18 -> 0
